using System;
using System.Threading;
using System.Threading.Tasks;
using Microsoft.VisualStudio.TestTools.UnitTesting;
using NeoSmart.AsyncLock;

namespace AsyncLockTests;

[TestClass]
public class CancellationTests
{
    [TestMethod]
    public void CancellingWait()
    {
        var @lock = new AsyncLock();
        var cts = new CancellationTokenSource(TimeSpan.FromSeconds(1));
        Task.Run(async () =>
        {
            await @lock.LockAsync(cts.Token);
        }).Wait();
        Assert.ThrowsExactlyAsync<OperationCanceledException>(async () =>
        {
            using (await @lock.LockAsync(cts.Token))
                Assert.Fail("should never reach here if cancellation works properly");
        }).Wait();

    }

    [TestMethod]
    public void CancellingWaitSync()
    {
        var asyncLock = new AsyncLock();
        var cts = new CancellationTokenSource(250);
        var delayStarted = new ManualResetEventSlim(false);
        var waiter1Finished = new SemaphoreSlim(0, 1);

        new Thread(() =>
        {
            using (asyncLock.Lock(cts.Token))
            {
                // hold the lock until our later attempt is called
                delayStarted.Set();
                waiter1Finished.Wait();
            }
        }).Start();

        Assert.ThrowsExactly<OperationCanceledException>(() =>
        {
            delayStarted.Wait();
            using (asyncLock.Lock(cts.Token))
            {
                Assert.Fail("should never reach here if cancellation works properly.");
            }
        });
        waiter1Finished.Release(1);

        // We should still be able to obtain a lock afterward to make sure resources were reobtained
        var newCts = new CancellationTokenSource(2000);
        using (asyncLock.Lock(newCts.Token))
        {
            // reaching this line means the test passed
            // a OperationCanceledException will indicate test failure
        }
    }
}
